<?xml version="1.0"?>
<robot name="Pioneer_2-AT_8">

<!--Se define el color de los materiales utilizados.-->

  <material name="red">
    <color rgba="0.851 0.0 0.0 1.0"/>
  </material>
  <material name="black">
    <color rgba="0.038 0.038 0.038 1.0"/>
  </material>
  <material name="yellow">
    <color rgba="0.715 0.583 0.210 1.0"/>
  </material>
    <material name="white">
    <color rgba="1.0 1.0 1.0 1.0"/>
  </material>

<!--Comenzamos definiendo cada una de las partes que componen el Pioneer y sus correspondientes uniones(joint)-->


<!-- Chasis -->

<link name="base_link">

    <visual>
      <geometry>
        <mesh filename="package://pioneer_description/meshes/chasis.stl"/>
      </geometry>
      <origin rpy="0 0 0" xyz="0 0 0.177"/>
      <material name="red"/>
    </visual>

    <collision>
      <geometry>
        <box size="0.5 0.38 0.19"/>
      </geometry>
      <origin rpy="0 0 0" xyz="0 0 0.177"/>
    </collision> 

    <inertial>
      <mass value="17"/>
      <!-- 14kg con una bateria mas otras 2 de 1,5kg cada una = 17kg-->
      <inertia ixx="0.256" ixy="0.0" ixz="0.0" iyy="0.405" iyz="0.0" izz="0.559"/>
      <!-- <inertia ixx="0.435" ixy="0.0" ixz="0.0" iyy="0.694" iyz="0.0" izz="0.4327"/>/>-->
      <origin xyz=" 0 0 0.177"/>
    </inertial>
    
 </link>


<!-- Cubierta superior -->

<link name="cubierta_link">

    <visual>
      <geometry>
        <mesh filename="package://pioneer_description/meshes/cubierta.stl"/>
        <origin rpy="0 0 0" xyz="0 0 0"/>
      </geometry>
      
      <material name="black"/>
    </visual>

    <collision>
      <geometry>
        <box size="0.51 0.38 0.03"/>
        <origin rpy="0 0 0" xyz="0 0 0"/>
      </geometry>
      
    </collision> 

    <inertial>
      <mass value="0.1"/>
      <!--Tomo un valor aproximado(Puede considerarse simbolico)-->
      <origin xyz="-0.025 0 -0.223"/>
      <inertia ixx="0.001" ixy="0.0" ixz="0.0" iyy="0.002" iyz="0.0" izz="0.003"/>
      
    </inertial>
    
 </link>

<joint name="base_cubierta" type="fixed">
    <origin  xyz="0.003 0 0.274" rpy="0 0 0" />
    <parent link="base_link"/>
    <child link="cubierta_link"/>
  </joint>

<!--Lidar sensor: --> 
<link name="hokuyo_link">
    <collision>
      <origin xyz="0 0 0" rpy="0 0 0"/>
      <geometry>
    <mesh filename="package://pioneer_description/meshes/hokuyo.dae"/>
      </geometry>
    </collision>

    <visual>
      <origin xyz="0 0 0" rpy="0 0 0"/>
      <geometry>
        <mesh filename="package://pioneer_description/meshes/hokuyo.dae"/>
      </geometry>
    </visual>

    <inertial>
      <mass value="1e-5" />
      <origin xyz="0 0 0" rpy="0 0 0"/>
      <inertia ixx="1e-6" ixy="0" ixz="0" iyy="1e-6" iyz="0" izz="1e-6" />
    </inertial>
  </link>

 <joint name="hokuyo_joint" type="fixed">
    <axis xyz="0 1 0" />
    <origin xyz="0.136 0 0.309" rpy="0 0 0"/>
    <parent link="base_link"/>
    <child link="hokuyo_link"/>
  </joint>

<!--Sonar sensor: --> 

<link name="Sonar_delantero_link">

    <visual>
      <geometry>
        <mesh filename="package://pioneer_description/meshes/sonar_delantero.stl"/>
      </geometry>
      <origin rpy="0 0 0" xyz="0 0 0"/>
      <material name="yellow"/>
    </visual>

    <collision>
      <geometry>
        <mesh filename="package://pioneer_description/meshes/sonar_delantero.stl"/>
      </geometry>
      <origin rpy="0 0 0" xyz="0 0 0"/>
    </collision> 

    <inertial>
      <mass value="0.1"/>
      <!--Tomo un valor aproximado(Puede considerarse simbolico)-->
      <!--<origin xyz="-0.025 0 -0.223"/>-->
      <inertia ixx="1e-6" ixy="0" ixz="0" iyy="1e-6" iyz="0" izz="1e-6" />
      <!--Matriz de inercias = 1 debido a su bajo efecto-->
    </inertial>

</link>


<link name="Sonar_trasero_link">

    <visual>
      <geometry>
        <mesh filename="package://pioneer_description/meshes/sonar_trasero.stl"/>
      </geometry>
      <origin rpy="0 0 0" xyz="0 0 0"/>
      <material name="yellow"/>
    </visual>

    <collision>
      <geometry>
        <mesh filename="package://pioneer_description/meshes/sonar_trasero.stl"/>
      </geometry>
      <origin rpy="0 0 0" xyz="0 0 0"/>
    </collision> 

    <inertial>
      <mass value="0.1"/>
      <!--Tomo un valor aproximado(Puede considerarse simbolico)-->
      <!--<origin xyz="-0.025 0 -0.223"/>-->
      <inertia ixx="1e-6" ixy="0" ixz="0" iyy="1e-6" iyz="0" izz="1e-6" />
      <!--Matriz de inercias = 1 debido a su bajo efecto-->
    </inertial>

</link>

<joint name="base_sonar_frontal_joint" type="fixed">
    <origin rpy="0 0 0" xyz="0.193 0 0.25"/>
    <parent link="base_link"/>
    <child link="Sonar_delantero_link"/>
  </joint>

<joint name="base_sonar_trasero_joint" type="fixed">
    <origin rpy="0 0 0" xyz="-0.187 0 0.247"/>
    <parent link="base_link"/>
    <child link="Sonar_trasero_link"/>
  </joint>


<!--Ruedas y ejes--> 
<link name="Eje_izq_delantero_link">
      <visual>
      <origin rpy="0 0 0" xyz="0 0 0"/>
      <geometry>
         <mesh filename="package://pioneer_description/meshes/eje.stl"/>
      </geometry>
      <material name="black"/>
    </visual>

    <collision>
      <origin rpy="0 0 0" xyz="0 0 0"/>
      <geometry>
        <mesh filename="package://pioneer_description/meshes/eje.stl"/>
      </geometry>
    </collision>

    <inertial>
      <mass value="0.2"/>
      <origin xyz="0 0 0"/>
      <inertia ixx="1e-6" ixy="0" ixz="0" iyy="1e-6" iyz="0" izz="1e-6" />
    </inertial>

  </link>
   
   <joint name="base_eje_izq_delantero_joint" type="fixed">
    <origin rpy="0 0 0" xyz="0.135 0.156 0.111"/>
    <parent link="base_link"/>
    <child link="Eje_izq_delantero_link"/>
  </joint>


<link name="Rueda_izq_delantera_link">
      <visual>
      <origin rpy="0 0 0" xyz="0 0 0"/>
      <geometry>
         <mesh filename="package://pioneer_description/meshes/rueda.stl"/>
      </geometry>
      <material name="black"/>
    </visual>

    <collision>
      <origin rpy="-1.57079635 0 0" xyz="0 0 0"/>
      <geometry>
        <cylinder length="0.075" radius="0.111"/>
      </geometry>
    </collision>

    <inertial>
      <mass value="1.4"/>
      <origin xyz="0 0 0"/>
      <inertia ixx="0.006" ixy="0" ixz="0" iyy="0.011" iyz="0" izz="0.006"/>
    </inertial>

  </link>

<joint name="base_ruedaizqdel_joint" type="continuous">
    <axis xyz="0 1 0"/>
    <!--<limit effort="80" velocity="0.268"/>-->
    <joint_properties damping="0.7"/>
    <origin rpy="0 0 0" xyz="0 0.041 0"/>
    <parent link="Eje_izq_delantero_link"/>
    <child link="Rueda_izq_delantera_link"/>
  </joint>

<gazebo reference="Rueda_izq_delantera_link">
      <mu1 value="200.0"/>
      <mu2 value="100.0"/>
      <kp value="10000000.0" />
      <kd value="1.0" />
      <material>Gazebo/Grey</material>
    </gazebo>

<transmission name="rueda_izq_delantera">
    <type>transmission_interface/SimpleTransmission</type>
    <actuator name="rueda_izq_del_motor">
      <mechanicalReduction>1</mechanicalReduction>
    </actuator>
    <joint name="base_ruedaizqdel_joint">
      <hardwareInterface>hardware_interface/VelocityJointInterface</hardwareInterface>
    </joint>
  </transmission>

<link name="Eje_der_delantero_link">
      <visual>
      <origin rpy="0 0 0" xyz="0 0 0"/>
      <geometry>
         <mesh filename="package://pioneer_description/meshes/eje.stl"/>
      </geometry>
      <material name="black"/>
    </visual>

    <collision>
      <origin rpy="0 0 0" xyz="0 0 0"/>
      <geometry>
        <mesh filename="package://pioneer_description/meshes/eje.stl"/>
      </geometry>
    </collision>

    <inertial>
      <mass value="0.2"/>
      <origin xyz="0 0 0"/>
      <inertia ixx="1e-6" ixy="0" ixz="0" iyy="1e-6" iyz="0" izz="1e-6" />
    </inertial>

  </link>
   
   <joint name="base_eje_der_delantero_joint" type="fixed">
    <origin rpy="0 0 0" xyz="0.135 -0.156 0.111"/>
    <parent link="base_link"/>
    <child link="Eje_der_delantero_link"/>
  </joint>

<link name="Rueda_der_delantera_link">
      <visual>
      <origin rpy="0 0 0" xyz="0 0 0"/>
      <geometry>
        <mesh filename="package://pioneer_description/meshes/rueda.stl"/>
      </geometry>
      <material name="black"/>
    </visual>

    <collision>
      <origin rpy="-1.57079635 0 0" xyz="0 0 0"/>
      <geometry>
        <cylinder length="0.075" radius="0.111"/>
      </geometry>
    </collision>

    <inertial>
      <mass value="1.4"/>
      <!--<origin xyz="0 0 0"/>-->
      <inertia ixx="0.006" ixy="0" ixz="0" iyy="0.011" iyz="0" izz="0.006"/>
    </inertial>

  </link>

<joint name="base_ruedaderdel_joint" type="continuous">
    <axis xyz="0 1 0"/>
    <!--<limit effort="80" velocity="0.268"/>-->
    <joint_properties damping="0.7"/>
    <origin rpy="0 0 0" xyz="0 -0.041 0"/>
    <parent link="Eje_der_delantero_link"/>
    <child link="Rueda_der_delantera_link"/>
  </joint>

<gazebo reference="Rueda_der_delantera_link">
      <mu1 value="200.0"/>
      <mu2 value="100.0"/>
      <kp value="10000000.0" />
      <kd value="1.0" />
      <material>Gazebo/Grey</material>
    </gazebo>

<transmission name="rueda_der_delantera">
    <type>transmission_interface/SimpleTransmission</type>
    <actuator name="rueda_der_del_motor">
      <mechanicalReduction>1</mechanicalReduction>
    </actuator>
    <joint name="base_ruedaderdel_joint">
      <hardwareInterface>hardware_interface/VelocityJointInterface</hardwareInterface>
    </joint>
  </transmission>

<link name="Eje_izq_trasero_link">
      <visual>
      <origin rpy="0 0 0" xyz="0 0 0"/>
      <geometry>
         <mesh filename="package://pioneer_description/meshes/eje.stl"/>
      </geometry>
      <material name="black"/>
    </visual>

    <collision>
      <origin rpy="0 0 0" xyz="0 0 0"/>
      <geometry>
        <mesh filename="package://pioneer_description/meshes/eje.stl"/>
      </geometry>
    </collision>

    <inertial>
      <mass value="0.2"/>
      <origin xyz="0 0 0"/>
      <inertia ixx="1e-6" ixy="0" ixz="0" iyy="1e-6" iyz="0" izz="1e-6" />
    </inertial>

  </link>
   
   <joint name="base_eje_izq_trasero_joint" type="fixed">
    <origin rpy="0 0 0" xyz="-0.135 0.156 0.111"/>
    <parent link="base_link"/>
    <child link="Eje_izq_trasero_link"/>
  </joint>

<link name="Rueda_izq_trasera_link">
      <visual>
      <origin rpy="0 0 0" xyz="0 0 0"/>
      <geometry>
        <mesh filename="package://pioneer_description/meshes/rueda.stl"/>
      </geometry>
      <material name="black"/>
    </visual>

    <collision>
      <origin rpy="-1.57079635 0 0" xyz="0 0 0"/>
      <geometry>
        <cylinder length="0.075" radius="0.111"/>
      </geometry>
    </collision>

    <inertial>
      <mass value="1.4"/>
      <!--<origin xyz="0 0 0"/>-->
      <inertia ixx="0.006" ixy="0" ixz="0" iyy="0.011" iyz="0" izz="0.006"/>
    </inertial>

  </link>

<joint name="base_ruedaizqtra_joint" type="continuous">
    <axis xyz="0 1 0"/>
    <!--<limit effort="80" velocity="0.268"/>-->
    <joint_properties damping="0.7"/>
    <origin rpy="0 0 0" xyz="0 0.041 0"/>
    <parent link="Eje_izq_trasero_link"/>
    <child link="Rueda_izq_trasera_link"/>
  </joint>

<gazebo reference="Rueda_izq_trasera_link">
      <mu1 value="200.0"/>
      <mu2 value="100.0"/>
      <kp value="10000000.0" />
      <kd value="1.0" />
      <material>Gazebo/Grey</material>
    </gazebo>

<transmission name="rueda_izq_trasera">
    <type>transmission_interface/SimpleTransmission</type>
    <actuator name="rueda_izq_tra_motor">
      <mechanicalReduction>1</mechanicalReduction>
    </actuator>
    <joint name="base_ruedaizqtra_joint">
      <hardwareInterface>hardware_interface/VelocityJointInterface</hardwareInterface>
    </joint>
  </transmission>


<link name="Eje_der_trasero_link">
      <visual>
      <origin rpy="0 0 0" xyz="0 0 0"/>
      <geometry>
         <mesh filename="package://pioneer_description/meshes/eje.stl"/>
      </geometry>
      <material name="black"/>
    </visual>

    <collision>
      <origin rpy="0 0 0" xyz="0 0 0"/>
      <geometry>
        <mesh filename="package://pioneer_description/meshes/eje.stl"/>
      </geometry>
    </collision>

    <inertial>
      <mass value="0.2"/>
      <origin xyz="0 0 0"/>
      <inertia ixx="1e-6" ixy="0" ixz="0" iyy="1e-6" iyz="0" izz="1e-6" />
    </inertial>

  </link>
   
   <joint name="base_eje_der_trasero_joint" type="fixed">
    <origin rpy="0 0 0" xyz="-0.135 -0.156 0.111"/>
    <parent link="base_link"/>
    <child link="Eje_der_trasero_link"/>
  </joint>

<link name="Rueda_der_trasera_link">
      <visual>
      <origin rpy="0 0 0" xyz="0 0 0"/>
      <geometry>
        <mesh filename="package://pioneer_description/meshes/rueda.stl"/>
      </geometry>
      <material name="black"/>
    </visual>

    <collision>
      <origin rpy="-1.57079635 0 0" xyz="0 0 0"/>
      <geometry>
        <cylinder length="0.075" radius="0.111"/>
      </geometry>
    </collision>

    <inertial>
      <mass value="1.4"/>
      <!--<origin xyz="0 0 0"/>-->
      <inertia ixx="0.006" ixy="0" ixz="0" iyy="0.011" iyz="0" izz="0.006"/>
    </inertial>

  </link>

<joint name="base_ruedadertra_joint" type="continuous">
    <axis xyz="0 1 0"/>
    <!--<limit effort="80" velocity="0.268"/>-->
    <joint_properties damping="0.7"/>
    <origin rpy="0 0 0" xyz="0 -0.041 0"/>
    <parent link="Eje_der_trasero_link"/>
    <child link="Rueda_der_trasera_link"/>
  </joint>

<gazebo reference="Rueda_der_trasera_link">
      <mu1 value="200.0"/>
      <mu2 value="100.0"/>
      <kp value="10000000.0" />
      <kd value="1.0" />
      <material>Gazebo/Grey</material>
    </gazebo>

<transmission name="rueda_der_trasera">
    <type>transmission_interface/SimpleTransmission</type>
    <actuator name="rueda_der_tra_motor">
      <mechanicalReduction>1</mechanicalReduction>
    </actuator>
    <joint name="base_ruedadertra_joint">
      <hardwareInterface>hardware_interface/VelocityJointInterface</hardwareInterface>
    </joint>
  </transmission>

  <!-- Gazebo plugin for ROS Control -->
  <gazebo>
    <plugin name="gazebo_ros_control" filename="libgazebo_ros_control.so">
      <robotNamespace>/</robotNamespace>
      <robotSimType>gazebo_ros_control/DefaultRobotHWSim</robotSimType>
    </plugin>
  </gazebo>

<!--Lidar plugin-->
<gazebo reference="hokuyo_link">
    <sensor type="gpu_ray" name="head_hokuyo_sensor">
      <pose>0 0 0 0 0 0</pose>
      <visualize>true</visualize>
      <update_rate>40</update_rate>
      <ray>
        <scan>
          <horizontal>
            <samples>720</samples>
            <resolution>1</resolution>
            <min_angle>-1.570796</min_angle>
            <max_angle>1.570796</max_angle>
          </horizontal>
        </scan>
        <range>
          <min>1</min>
          <max>15.0</max>
          <resolution>0.01</resolution>
        </range>
        <noise>
          <type>gaussian</type>
          <!-- Noise parameters based on published spec for Hokuyo laser
               achieving "+-30mm" accuracy at range < 10m.  A mean of 0.0m and
               stddev of 0.01m will put 99.7% of samples within 0.03m of the true
               reading. -->
          <mean>0.0</mean>
          <stddev>0.01</stddev>
        </noise>
      </ray>
      <plugin name="gazebo_ros_head_hokuyo_controller" filename="libgazebo_gpu_ros_laser.so">
        <topicName>/laser/scan</topicName>
        <frameName>hokuyo_link</frameName>
        <visualize>true</visualize>
        <always_on>1</always_on>
      </plugin>
    </sensor>
  </gazebo>

<gazebo reference="base_link">
      <material>Gazebo/Red</material>
</gazebo>

<gazebo reference="cubierta_link">
      <material>Gazebo/Black</material>
</gazebo>

<gazebo reference="Sonar_delantero_link">
      <material>Gazebo/Yellow</material>
</gazebo>

<gazebo reference="Sonar_trasero_link">
      <material>Gazebo/Yellow</material>
</gazebo>
<gazebo reference="Eje_izq_delantero_link">
      <material>Gazebo/Black</material>
</gazebo>
<gazebo reference="Eje_der_delantero_link">
      <material>Gazebo/Black</material>
</gazebo>
<gazebo reference="Eje_izq_trasero_link">
      <material>Gazebo/Black</material>
</gazebo>
<gazebo reference="Eje_der_trasero_link">
      <material>Gazebo/Black</material>
</gazebo>
</robot>


 
